Workbook

Sheet ⚡ COMMAND TRACKER
A1: ⚡ eCON GROWTH · COMMAND OS COLD CALL INTELLIGENCE · POWERED BY Roger AI
A2: 🏢 COMPANY INTEL | I2: 📞 CALL INTELLIGENCE | Q2: 🔥 PAIN MATRIX | W2: 🎯 CONVERSION | AA2: 🤖 AI FIT ENGINE | AD2: 📅 FOLLOW-UP SYSTEM
A3: Company Name | B3: Phone | C3: City | D3: Website | E3: Owners Name | F3: Owners Email | G3: Role | H3: # Trucks | I3: Answer Status | J3: Person Reached | K3: Got Email? | L3: Opening Reaction | M3: Main Pain | N3: Call Notes | O3: Call Recording Link | P3: Call Transcription Link | Q3: Recruiting Pain | R3: Retention Pain | S3: Ops/System Pain | T3: Revenue Pain | U3: Pain Detail | V3: Pain Score | W3: Open to Meeting? | X3: Meeting Type | Y3: Objection | Z3: Follow-Up Action | AA3: Fit Score | AB3: Fit Tier | AC3: Priority | AD3: Last Call | AE3: Callback Date | AF3: Days Until Call | AG3: Caller
A5: Crank it HVAC | B5: (801) 815-3222 | C5: West Jordan | D5: Click Here | E5: NA | F5: NA | G5: Owner | H5: NA | I5: Answered | J5: Owner | K5: No | L5: Not Interested | M5: Revenue/Cash Flow | N5: Residental Remodels | O5: NA | Q5: Minor | R5: Minor | S5: None | T5: Minor | U5: They do remodels no retro-fits | V5: =IFERROR(ROUND((IF(Q5="Severe",4,IF(Q5="Moderate",3,IF(Q5="Minor",2,0)))+IF(R5="Severe",4,IF(R5="Moderate",3,IF(R5="Minor",2,0)))+IF(S5="Severe",4,IF(S5="Moderate",3,IF(S5="Minor",2,0)))+IF(T5="Severe",4,IF(T5="Moderate",3,IF(T5="Minor",2,0))))/16*100,0),"") | W5: No | X5: None Yet | Y5: They Dont Think They Need it | Z5: Send Text | AA5: =IFERROR(ROUND(IF(H5>=10,30,IF(H5>=5,20,IF(H5>=2,10,0)))+IF(K5="Yes",20,IF(K5="Unsure",10,0))+IF(W5="Yes",30,IF(W5="Later",15,0))+IFERROR(V5/100*20,0)+IF(L5="Interested",15,IF(L5="Open But Busy",10,IF(L5="Neutral",5,0))),0),"") | AB5: =IFERROR(IF(AA5>=80,"🔥 HOT",IF(AA5>=60,"✅ STRONG",IF(AA5>=40,"⚡ WARM",IF(AA5>=20,"📋 NURTURE",IF(AA5>0,"❌ COLD",""))))),"") | AC5: =IFERROR(IF(AND(AA5>=60,OR(W5="Yes",W5="Later")),"🚨 URGENT",IF(AND(AA5>=40,I5="Call Back"),"📞 CALL BACK",IF(I5="Booked Meeting","📅 BOOKED",IF(I5="Not Interested","🚫 DEAD","⏳ WORKING")))),"") | AD5: 04/15/26@4:38pm | AE5: 46133 | AF5: =IFERROR(IF(AE5="","",AE5-TODAY()),"") | AG5: Kristopher
A6: BNZ Heating & Air | B6: (385)831-0553 | C6: Herriman | D6: Click Here | E6: NA | F6: NA | G6: CSR? | H6: NA | I6: Answered | J6: NA | K6: No | L6: Not Interested | M6: No Clear Pain Point | N6: Said they have a system that they love but didnt know the name | O6: NA | Q6: Moderate | R6: Minor | S6: Minor | T6: Severe | U6: Verry Rude Not Open to a conversation | V6: =IFERROR(ROUND((IF(Q6="Severe",4,IF(Q6="Moderate",3,IF(Q6="Minor",2,0)))+IF(R6="Severe",4,IF(R6="Moderate",3,IF(R6="Minor",2,0)))+IF(S6="Severe",4,IF(S6="Moderate",3,IF(S6="Minor",2,0)))+IF(T6="Severe",4,IF(T6="Moderate",3,IF(T6="Minor",2,0))))/16*100,0),"") | W6: No | X6: None Yet | Y6: Have a system they Love | Z6: Call Back | AA6: =IFERROR(ROUND(IF(H6>=10,30,IF(H6>=5,20,IF(H6>=2,10,0)))+IF(K6="Yes",20,IF(K6="Unsure",10,0))+IF(W6="Yes",30,IF(W6="Later",15,0))+IFERROR(V6/100*20,0)+IF(L6="Interested",15,IF(L6="Open But Busy",10,IF(L6="Neutral",5,0))),0),"") | AB6: =IFERROR(IF(AA6>=80,"🔥 HOT",IF(AA6>=60,"✅ STRONG",IF(AA6>=40,"⚡ WARM",IF(AA6>=20,"📋 NURTURE",IF(AA6>0,"❌ COLD",""))))),"") | AC6: =IFERROR(IF(AND(AA6>=60,OR(W6="Yes",W6="Later")),"🚨 URGENT",IF(AND(AA6>=40,I6="Call Back"),"📞 CALL BACK",IF(I6="Booked Meeting","📅 BOOKED",IF(I6="Not Interested","🚫 DEAD","⏳ WORKING")))),"") | AD6: 04/15/26@4:46pm | AE6: 46128 | AF6: =IFERROR(IF(AE6="","",AE6-TODAY()),"") | AG6: Kristopher
A7: Hansen HVAC Heating & Cooling | B7: (801)280-8812 | C7: West Jordan | D7: Click Here | E7: 3 Dudes & Chick | F7: info@hansenhvacservices.com | G7: Owners/Son | H7: 10+ | I7: Answered | J7: Riley/Tech | K7: Yes | L7: Hostile | M7: Training | N7: Riley said that the top tax do not have a problem selling, it's always the younger guys, always telling the homeowners when they take emergency calls on weekends, that it's going to be more money, it's more expensive to have me come out, so the newer guys have a hard time selling. | O7: NA | Q7: Moderate | R7: Moderate | S7: Moderate | T7: Moderate | U7: The new guys are having a hard time selling, or declining emergency calls. | V7: =IFERROR(ROUND((IF(Q7="Severe",4,IF(Q7="Moderate",3,IF(Q7="Minor",2,0)))+IF(R7="Severe",4,IF(R7="Moderate",3,IF(R7="Minor",2,0)))+IF(S7="Severe",4,IF(S7="Moderate",3,IF(S7="Minor",2,0)))+IF(T7="Severe",4,IF(T7="Moderate",3,IF(T7="Minor",2,0))))/16*100,0),"") | W7: Yes | X7: Phone | Y7: None they tink it sounds amazing | Z7: Call Back | AA7: =IFERROR(ROUND(IF(H7>=10,30,IF(H7>=5,20,IF(H7>=2,10,0)))+IF(K7="Yes",20,IF(K7="Unsure",10,0))+IF(W7="Yes",30,IF(W7="Later",15,0))+IFERROR(V7/100*20,0)+IF(L7="Interested",15,IF(L7="Open But Busy",10,IF(L7="Neutral",5,0))),0),"") | AB7: =IFERROR(IF(AA7>=80,"🔥 HOT",IF(AA7>=60,"✅ STRONG",IF(AA7>=40,"⚡ WARM",IF(AA7>=20,"📋 NURTURE",IF(AA7>0,"❌ COLD",""))))),"") | AC7: =IFERROR(IF(AND(AA7>=60,OR(W7="Yes",W7="Later")),"🚨 URGENT",IF(AND(AA7>=40,I7="Call Back"),"📞 CALL BACK",IF(I7="Booked Meeting","📅 BOOKED",IF(I7="Not Interested","🚫 DEAD","⏳ WORKING")))),"") | AD7: 4/15/2026@4:54pm | AE7: 46128 | AF7: =IFERROR(IF(AE7="","",AE7-TODAY()),"") | AG7: Kristopher
A8: Valley Plumbing Heating & Cooling | B8: (385)276-4284 | C8: West Jordan | D8: Click Here | E8: NA | F8: NA | G8: NA | H8: NA | I8: Left Voicemail | J8: NA | K8: No | L8: NA | M8: Scheduling | N8: No Answer Call Back Scheduled For 04/16/2026 | O8: NA | Q8: NA | R8: NA | S8: Severe | T8: Severe | U8: NA | V8: =IFERROR(ROUND((IF(Q8="Severe",4,IF(Q8="Moderate",3,IF(Q8="Minor",2,0)))+IF(R8="Severe",4,IF(R8="Moderate",3,IF(R8="Minor",2,0)))+IF(S8="Severe",4,IF(S8="Moderate",3,IF(S8="Minor",2,0)))+IF(T8="Severe",4,IF(T8="Moderate",3,IF(T8="Minor",2,0))))/16*100,0),"") | W8: Later | X8: None Yet | Y8: NA | Z8: Call Back | AA8: =IFERROR(ROUND(IF(H8>=10,30,IF(H8>=5,20,IF(H8>=2,10,0)))+IF(K8="Yes",20,IF(K8="Unsure",10,0))+IF(W8="Yes",30,IF(W8="Later",15,0))+IFERROR(V8/100*20,0)+IF(L8="Interested",15,IF(L8="Open But Busy",10,IF(L8="Neutral",5,0))),0),"") | AB8: =IFERROR(IF(AA8>=80,"🔥 HOT",IF(AA8>=60,"✅ STRONG",IF(AA8>=40,"⚡ WARM",IF(AA8>=20,"📋 NURTURE",IF(AA8>0,"❌ COLD",""))))),"") | AC8: =IFERROR(IF(AND(AA8>=60,OR(W8="Yes",W8="Later")),"🚨 URGENT",IF(AND(AA8>=40,I8="Call Back"),"📞 CALL BACK",IF(I8="Booked Meeting","📅 BOOKED",IF(I8="Not Interested","🚫 DEAD","⏳ WORKING")))),"") | AD8: 04/15/2026@5:14pm | AE8: 46128 | AF8: =IFERROR(IF(AE8="","",AE8-TODAY()),"") | AG8: Kristopher
A9: West Jordan HVAC | B9: (801)843-3202 | C9: West Jordan | D9: NO WEBSITE | E9: NA | F9: NA | G9: NA | H9: NA | I9: No Answer | J9: NA | K9: No | L9: NA | M9: Scheduling | N9: No Answer Call Back Scheduled For 04/16/2026 | O9: NA | Q9: NA | R9: NA | S9: Severe | T9: Severe | U9: NA | V9: =IFERROR(ROUND((IF(Q9="Severe",4,IF(Q9="Moderate",3,IF(Q9="Minor",2,0)))+IF(R9="Severe",4,IF(R9="Moderate",3,IF(R9="Minor",2,0)))+IF(S9="Severe",4,IF(S9="Moderate",3,IF(S9="Minor",2,0)))+IF(T9="Severe",4,IF(T9="Moderate",3,IF(T9="Minor",2,0))))/16*100,0),"") | W9: Later | X9: None Yet | Y9: NA | Z9: Call Back | AA9: =IFERROR(ROUND(IF(H9>=10,30,IF(H9>=5,20,IF(H9>=2,10,0)))+IF(K9="Yes",20,IF(K9="Unsure",10,0))+IF(W9="Yes",30,IF(W9="Later",15,0))+IFERROR(V9/100*20,0)+IF(L9="Interested",15,IF(L9="Open But Busy",10,IF(L9="Neutral",5,0))),0),"") | AB9: =IFERROR(IF(AA9>=80,"🔥 HOT",IF(AA9>=60,"✅ STRONG",IF(AA9>=40,"⚡ WARM",IF(AA9>=20,"📋 NURTURE",IF(AA9>0,"❌ COLD",""))))),"") | AC9: =IFERROR(IF(AND(AA9>=60,OR(W9="Yes",W9="Later")),"🚨 URGENT",IF(AND(AA9>=40,I9="Call Back"),"📞 CALL BACK",IF(I9="Booked Meeting","📅 BOOKED",IF(I9="Not Interested","🚫 DEAD","⏳ WORKING")))),"") | AD9: 04/15/2026@5:15pm | AE9: 46128 | AF9: =IFERROR(IF(AE9="","",AE9-TODAY()),"") | AG9: Kristopher
A10: Titan Heating & Air Conditioning | B10: (801)972-0905 | C10: West Jordan | D10: Click Here | E10: NA | F10: NA | G10: NA | H10: NA | I10: Left Voicemail | J10: NA | K10: No | L10: NA | M10: Scheduling | N10: No Answer Call Back Scheduled For 04/16/2026 | O10: NA | Q10: NA | R10: NA | S10: Severe | T10: Severe | U10: NA | V10: =IFERROR(ROUND((IF(Q10="Severe",4,IF(Q10="Moderate",3,IF(Q10="Minor",2,0)))+IF(R10="Severe",4,IF(R10="Moderate",3,IF(R10="Minor",2,0)))+IF(S10="Severe",4,IF(S10="Moderate",3,IF(S10="Minor",2,0)))+IF(T10="Severe",4,IF(T10="Moderate",3,IF(T10="Minor",2,0))))/16*100,0),"") | W10: Later | X10: None Yet | Y10: NA | Z10: Call Back | AA10: =IFERROR(ROUND(IF(H10>=10,30,IF(H10>=5,20,IF(H10>=2,10,0)))+IF(K10="Yes",20,IF(K10="Unsure",10,0))+IF(W10="Yes",30,IF(W10="Later",15,0))+IFERROR(V10/100*20,0)+IF(L10="Interested",15,IF(L10="Open But Busy",10,IF(L10="Neutral",5,0))),0),"") | AB10: =IFERROR(IF(AA10>=80,"🔥 HOT",IF(AA10>=60,"✅ STRONG",IF(AA10>=40,"⚡ WARM",IF(AA10>=20,"📋 NURTURE",IF(AA10>0,"❌ COLD",""))))),"") | AC10: =IFERROR(IF(AND(AA10>=60,OR(W10="Yes",W10="Later")),"🚨 URGENT",IF(AND(AA10>=40,I10="Call Back"),"📞 CALL BACK",IF(I10="Booked Meeting","📅 BOOKED",IF(I10="Not Interested","🚫 DEAD","⏳ WORKING")))),"") | AD10: 04/15/2026@5:16pm | AE10: 46128 | AF10: =IFERROR(IF(AE10="","",AE10-TODAY()),"") | AG10: Kristopher
A11: All Utah Plumbing Heating & Air | B11: (801)652-4755 | C11: West Jordan | D11: Click Here | E11: NA | F11: NA | G11: CSR | H11: NA | I11: Answered | J11: Wayne/CSR | K11: No | L11: Neutral | M11: No Clear Pain Point | N11: The already have an AI Named Broccoli will call in 1 month from now to see how they are doing | O11: NA | Q11: Minor | R11: Minor | S11: Minor | T11: Severe | U11: Testing the AI RN | V11: =IFERROR(ROUND((IF(Q11="Severe",4,IF(Q11="Moderate",3,IF(Q11="Minor",2,0)))+IF(R11="Severe",4,IF(R11="Moderate",3,IF(R11="Minor",2,0)))+IF(S11="Severe",4,IF(S11="Moderate",3,IF(S11="Minor",2,0)))+IF(T11="Severe",4,IF(T11="Moderate",3,IF(T11="Minor",2,0))))/16*100,0),"") | W11: Later | X11: Phone | Y11: Just testing what they have and if they dont like it they will tell me in 1 Month | Z11: Call Back | AA11: =IFERROR(ROUND(IF(H11>=10,30,IF(H11>=5,20,IF(H11>=2,10,0)))+IF(K11="Yes",20,IF(K11="Unsure",10,0))+IF(W11="Yes",30,IF(W11="Later",15,0))+IFERROR(V11/100*20,0)+IF(L11="Interested",15,IF(L11="Open But Busy",10,IF(L11="Neutral",5,0))),0),"") | AB11: =IFERROR(IF(AA11>=80,"🔥 HOT",IF(AA11>=60,"✅ STRONG",IF(AA11>=40,"⚡ WARM",IF(AA11>=20,"📋 NURTURE",IF(AA11>0,"❌ COLD",""))))),"") | AC11: =IFERROR(IF(AND(AA11>=60,OR(W11="Yes",W11="Later")),"🚨 URGENT",IF(AND(AA11>=40,I11="Call Back"),"📞 CALL BACK",IF(I11="Booked Meeting","📅 BOOKED",IF(I11="Not Interested","🚫 DEAD","⏳ WORKING")))),"") | AD11: 04/15/2026@5:26pm | AE11: 46158 | AF11: =IFERROR(IF(AE11="","",AE11-TODAY()),"") | AG11: Kristopher
A12: Thomas Brothers Heating & Air Conditioning | B12: (385)503-3030 | C12: West Jordan | D12: Click Here | E12: NA | F12: NA | G12: NA | H12: NA | I12: Bad Number | J12: NA | K12: No | L12: NA | M12: Operations/System | N12: No Answer Call Back Scheduled For 04/17/2026 | O12: NA | R12: NA | S12: Severe | T12: Severe | U12: NA | V12: =IFERROR(ROUND((IF(Q12="Severe",4,IF(Q12="Moderate",3,IF(Q12="Minor",2,0)))+IF(R12="Severe",4,IF(R12="Moderate",3,IF(R12="Minor",2,0)))+IF(S12="Severe",4,IF(S12="Moderate",3,IF(S12="Minor",2,0)))+IF(T12="Severe",4,IF(T12="Moderate",3,IF(T12="Minor",2,0))))/16*100,0),"") | W12: Later | X12: None Yet | Y12: NA | Z12: Call Back | AA12: =IFERROR(ROUND(IF(H12>=10,30,IF(H12>=5,20,IF(H12>=2,10,0)))+IF(K12="Yes",20,IF(K12="Unsure",10,0))+IF(W12="Yes",30,IF(W12="Later",15,0))+IFERROR(V12/100*20,0)+IF(L12="Interested",15,IF(L12="Open But Busy",10,IF(L12="Neutral",5,0))),0),"") | AB12: =IFERROR(IF(AA12>=80,"🔥 HOT",IF(AA12>=60,"✅ STRONG",IF(AA12>=40,"⚡ WARM",IF(AA12>=20,"📋 NURTURE",IF(AA12>0,"❌ COLD",""))))),"") | AC12: =IFERROR(IF(AND(AA12>=60,OR(W12="Yes",W12="Later")),"🚨 URGENT",IF(AND(AA12>=40,I12="Call Back"),"📞 CALL BACK",IF(I12="Booked Meeting","📅 BOOKED",IF(I12="Not Interested","🚫 DEAD","⏳ WORKING")))),"") | AD12: 04/16/2026@12:54pm | AE12: 46129 | AF12: =IFERROR(IF(AE12="","",AE12-TODAY()),"") | AG12: Kristopher
A13: Wasatch Peaks Heating & Air Conditoning | B13: (801)332-9790 | C13: West Jordan | D13: Click Here | E13: Justin | F13: jwoodson@wpeakshvac.com | G13: Owner | H13: 5+ | I13: Answered | J13: Justin/Owner | K13: Yes | L13: Open But Busy | M13: Operations/System | N13: He said that his whole install crew is in Ohio right now, and he is the one doing the installs so 1 week push | O13: NA | Q13: Severe | R13: Minor | S13: Severe | T13: Moderate | U13: First Demo Scheduled 1 Week From Today | V13: =IFERROR(ROUND((IF(Q13="Severe",4,IF(Q13="Moderate",3,IF(Q13="Minor",2,0)))+IF(R13="Severe",4,IF(R13="Moderate",3,IF(R13="Minor",2,0)))+IF(S13="Severe",4,IF(S13="Moderate",3,IF(S13="Minor",2,0)))+IF(T13="Severe",4,IF(T13="Moderate",3,IF(T13="Minor",2,0))))/16*100,0),"") | W13: Yes | X13: Zoom | Y13: Just really busy and cant do today | Z13: Book Zoom | AA13: =IFERROR(ROUND(IF(H13>=10,30,IF(H13>=5,20,IF(H13>=2,10,0)))+IF(K13="Yes",20,IF(K13="Unsure",10,0))+IF(W13="Yes",30,IF(W13="Later",15,0))+IFERROR(V13/100*20,0)+IF(L13="Interested",15,IF(L13="Open But Busy",10,IF(L13="Neutral",5,0))),0),"") | AB13: =IFERROR(IF(AA13>=80,"🔥 HOT",IF(AA13>=60,"✅ STRONG",IF(AA13>=40,"⚡ WARM",IF(AA13>=20,"📋 NURTURE",IF(AA13>0,"❌ COLD",""))))),"") | AC13: =IFERROR(IF(AND(AA13>=60,OR(W13="Yes",W13="Later")),"🚨 URGENT",IF(AND(AA13>=40,I13="Call Back"),"📞 CALL BACK",IF(I13="Booked Meeting","📅 BOOKED",IF(I13="Not Interested","🚫 DEAD","⏳ WORKING")))),"") | AD13: 04/16/2026@12:56pm | AE13: 46135 | AF13: =IFERROR(IF(AE13="","",AE13-TODAY()),"") | AG13: Kristopher
A14: All Around Cooling & Heating | B14: (385)899-2576 | C14: West Jordan | D14: Click Here | E14: NA | F14: NA | G14: NA | H14: NA | I14: Left Voicemail | J14: NA | K14: No | L14: NA | M14: Scheduling | N14: NA | O14: NA | Q14: NA | R14: NA | S14: Severe | T14: Severe | U14: NA | V14: =IFERROR(ROUND((IF(Q14="Severe",4,IF(Q14="Moderate",3,IF(Q14="Minor",2,0)))+IF(R14="Severe",4,IF(R14="Moderate",3,IF(R14="Minor",2,0)))+IF(S14="Severe",4,IF(S14="Moderate",3,IF(S14="Minor",2,0)))+IF(T14="Severe",4,IF(T14="Moderate",3,IF(T14="Minor",2,0))))/16*100,0),"") | W14: Later | X14: None Yet | Y14: NA | Z14: Call Back | AA14: =IFERROR(ROUND(IF(H14>=10,30,IF(H14>=5,20,IF(H14>=2,10,0)))+IF(K14="Yes",20,IF(K14="Unsure",10,0))+IF(W14="Yes",30,IF(W14="Later",15,0))+IFERROR(V14/100*20,0)+IF(L14="Interested",15,IF(L14="Open But Busy",10,IF(L14="Neutral",5,0))),0),"") | AB14: =IFERROR(IF(AA14>=80,"🔥 HOT",IF(AA14>=60,"✅ STRONG",IF(AA14>=40,"⚡ WARM",IF(AA14>=20,"📋 NURTURE",IF(AA14>0,"❌ COLD",""))))),"") | AC14: =IFERROR(IF(AND(AA14>=60,OR(W14="Yes",W14="Later")),"🚨 URGENT",IF(AND(AA14>=40,I14="Call Back"),"📞 CALL BACK",IF(I14="Booked Meeting","📅 BOOKED",IF(I14="Not Interested","🚫 DEAD","⏳ WORKING")))),"") | AD14: 04/16/2026@2:24pm | AE14: 46129 | AF14: =IFERROR(IF(AE14="","",AE14-TODAY()),"") | AG14: Kristopher
A15: Larsen HVAC & Plumbing | B15: (801)930-5450 | C15: West Jordan | D15: Click Here | E15: Sean | F15: NA | G15: NA | H15: NA | I15: Answered | J15: OWNER | K15: No | L15: Hostile | M15: Retention | N15: They said they have AI but system Didint answer for them | O15: NA | Q15: Moderate | R15: Severe | S15: Severe | T15: Moderate | U15: Sean said that they have AI and that they're not interested, and it was real quick to just get off the phone — didn't really want to communicate at all.. | V15: =IFERROR(ROUND((IF(Q15="Severe",4,IF(Q15="Moderate",3,IF(Q15="Minor",2,0)))+IF(R15="Severe",4,IF(R15="Moderate",3,IF(R15="Minor",2,0)))+IF(S15="Severe",4,IF(S15="Moderate",3,IF(S15="Minor",2,0)))+IF(T15="Severe",4,IF(T15="Moderate",3,IF(T15="Minor",2,0))))/16*100,0),"") | W15: Later | X15: None Yet | Y15: He said they have AI and they are okay, but it's clear that whatever system he thinks he has is not meeting the needs of the company. | Z15: Call Back | AA15: =IFERROR(ROUND(IF(H15>=10,30,IF(H15>=5,20,IF(H15>=2,10,0)))+IF(K15="Yes",20,IF(K15="Unsure",10,0))+IF(W15="Yes",30,IF(W15="Later",15,0))+IFERROR(V15/100*20,0)+IF(L15="Interested",15,IF(L15="Open But Busy",10,IF(L15="Neutral",5,0))),0),"") | AB15: =IFERROR(IF(AA15>=80,"🔥 HOT",IF(AA15>=60,"✅ STRONG",IF(AA15>=40,"⚡ WARM",IF(AA15>=20,"📋 NURTURE",IF(AA15>0,"❌ COLD",""))))),"") | AC15: =IFERROR(IF(AND(AA15>=60,OR(W15="Yes",W15="Later")),"🚨 URGENT",IF(AND(AA15>=40,I15="Call Back"),"📞 CALL BACK",IF(I15="Booked Meeting","📅 BOOKED",IF(I15="Not Interested","🚫 DEAD","⏳ WORKING")))),"") | AD15: 04/16/2026@2:26pm | AE15: 46132 | AF15: =IFERROR(IF(AE15="","",AE15-TODAY()),"") | AG15: Kristopher
A16: Dynamic HVAC | B16: (801)852-8360 | C16: West Jordan | D16: Click Here | E16: Doug | F16: NA | G16: NA | H16: NA | I16: No Answer | J16: NA | K16: No | L16: NA | M16: Scheduling | N16: NA | O16: NA | Q16: NA | R16: NA | S16: Severe | T16: Severe | U16: NA | V16: =IFERROR(ROUND((IF(Q16="Severe",4,IF(Q16="Moderate",3,IF(Q16="Minor",2,0)))+IF(R16="Severe",4,IF(R16="Moderate",3,IF(R16="Minor",2,0)))+IF(S16="Severe",4,IF(S16="Moderate",3,IF(S16="Minor",2,0)))+IF(T16="Severe",4,IF(T16="Moderate",3,IF(T16="Minor",2,0))))/16*100,0),"") | W16: Later | X16: None Yet | Y16: NA | Z16: Call Back | AA16: =IFERROR(ROUND(IF(H16>=10,30,IF(H16>=5,20,IF(H16>=2,10,0)))+IF(K16="Yes",20,IF(K16="Unsure",10,0))+IF(W16="Yes",30,IF(W16="Later",15,0))+IFERROR(V16/100*20,0)+IF(L16="Interested",15,IF(L16="Open But Busy",10,IF(L16="Neutral",5,0))),0),"") | AB16: =IFERROR(IF(AA16>=80,"🔥 HOT",IF(AA16>=60,"✅ STRONG",IF(AA16>=40,"⚡ WARM",IF(AA16>=20,"📋 NURTURE",IF(AA16>0,"❌ COLD",""))))),"") | AC16: =IFERROR(IF(AND(AA16>=60,OR(W16="Yes",W16="Later")),"🚨 URGENT",IF(AND(AA16>=40,I16="Call Back"),"📞 CALL BACK",IF(I16="Booked Meeting","📅 BOOKED",IF(I16="Not Interested","🚫 DEAD","⏳ WORKING")))),"") | AD16: 04/16/2026@2:33pm | AE16: 46129 | AF16: =IFERROR(IF(AE16="","",AE16-TODAY()),"") | AG16: Kristopher
A17: J & M Plumbing Heating & Air | B17: (801)566-0141 | C17: West Jordan | D17: Click Here | E17: NA | F17: NA | G17: NA | H17: NA | I17: Answered | J17: CSR/Angle | K17: No | L17: Not Interested | M17: Revenue/Cash Flow | N17: NA | O17: NA | Q17: NA | R17: NA | S17: Moderate | T17: Severe | U17: NA | V17: =IFERROR(ROUND((IF(Q17="Severe",4,IF(Q17="Moderate",3,IF(Q17="Minor",2,0)))+IF(R17="Severe",4,IF(R17="Moderate",3,IF(R17="Minor",2,0)))+IF(S17="Severe",4,IF(S17="Moderate",3,IF(S17="Minor",2,0)))+IF(T17="Severe",4,IF(T17="Moderate",3,IF(T17="Minor",2,0))))/16*100,0),"") | W17: Later | X17: None Yet | Y17: NA | Z17: Call Back | AA17: =IFERROR(ROUND(IF(H17>=10,30,IF(H17>=5,20,IF(H17>=2,10,0)))+IF(K17="Yes",20,IF(K17="Unsure",10,0))+IF(W17="Yes",30,IF(W17="Later",15,0))+IFERROR(V17/100*20,0)+IF(L17="Interested",15,IF(L17="Open But Busy",10,IF(L17="Neutral",5,0))),0),"") | AB17: =IFERROR(IF(AA17>=80,"🔥 HOT",IF(AA17>=60,"✅ STRONG",IF(AA17>=40,"⚡ WARM",IF(AA17>=20,"📋 NURTURE",IF(AA17>0,"❌ COLD",""))))),"") | AC17: =IFERROR(IF(AND(AA17>=60,OR(W17="Yes",W17="Later")),"🚨 URGENT",IF(AND(AA17>=40,I17="Call Back"),"📞 CALL BACK",IF(I17="Booked Meeting","📅 BOOKED",IF(I17="Not Interested","🚫 DEAD","⏳ WORKING")))),"") | AD17: 04/16/2026@2:36pm | AE17: 46129 | AF17: =IFERROR(IF(AE17="","",AE17-TODAY()),"") | AG17: Kristopher
A18: Arrow HVAC | B18: (801)515-4096 | C18: West Jordan | D18: Click Here | E18: NA | F18: NA | G18: NA | H18: NA | I18: No Answer | J18: NA | K18: No | L18: NA | M18: Scheduling | N18: NA | O18: NA | Q18: NA | R18: NA | S18: Severe | T18: Severe | U18: NA | V18: =IFERROR(ROUND((IF(Q18="Severe",4,IF(Q18="Moderate",3,IF(Q18="Minor",2,0)))+IF(R18="Severe",4,IF(R18="Moderate",3,IF(R18="Minor",2,0)))+IF(S18="Severe",4,IF(S18="Moderate",3,IF(S18="Minor",2,0)))+IF(T18="Severe",4,IF(T18="Moderate",3,IF(T18="Minor",2,0))))/16*100,0),"") | W18: Later | X18: None Yet | Y18: NA | Z18: Call Back | AA18: =IFERROR(ROUND(IF(H18>=10,30,IF(H18>=5,20,IF(H18>=2,10,0)))+IF(K18="Yes",20,IF(K18="Unsure",10,0))+IF(W18="Yes",30,IF(W18="Later",15,0))+IFERROR(V18/100*20,0)+IF(L18="Interested",15,IF(L18="Open But Busy",10,IF(L18="Neutral",5,0))),0),"") | AB18: =IFERROR(IF(AA18>=80,"🔥 HOT",IF(AA18>=60,"✅ STRONG",IF(AA18>=40,"⚡ WARM",IF(AA18>=20,"📋 NURTURE",IF(AA18>0,"❌ COLD",""))))),"") | AC18: =IFERROR(IF(AND(AA18>=60,OR(W18="Yes",W18="Later")),"🚨 URGENT",IF(AND(AA18>=40,I18="Call Back"),"📞 CALL BACK",IF(I18="Booked Meeting","📅 BOOKED",IF(I18="Not Interested","🚫 DEAD","⏳ WORKING")))),"") | AD18: 04/16/2026@2:40pm | AE18: 46129 | AF18: =IFERROR(IF(AE18="","",AE18-TODAY()),"") | AG18: Kristopher
A19: Huish Heating & AC | B19: (801)971-3418 | C19: Salt Lake City | D19: Click Here | E19: NA | F19: NA | G19: NA | H19: NA | I19: No Answer | J19: NA | K19: No | L19: NA | M19: Scheduling | N19: NA | O19: NA | Q19: NA | R19: NA | S19: Severe | T19: Severe | U19: NA | V19: =IFERROR(ROUND((IF(Q19="Severe",4,IF(Q19="Moderate",3,IF(Q19="Minor",2,0)))+IF(R19="Severe",4,IF(R19="Moderate",3,IF(R19="Minor",2,0)))+IF(S19="Severe",4,IF(S19="Moderate",3,IF(S19="Minor",2,0)))+IF(T19="Severe",4,IF(T19="Moderate",3,IF(T19="Minor",2,0))))/16*100,0),"") | W19: Later | X19: None Yet | Y19: NA | Z19: Call Back | AA19: =IFERROR(ROUND(IF(H19>=10,30,IF(H19>=5,20,IF(H19>=2,10,0)))+IF(K19="Yes",20,IF(K19="Unsure",10,0))+IF(W19="Yes",30,IF(W19="Later",15,0))+IFERROR(V19/100*20,0)+IF(L19="Interested",15,IF(L19="Open But Busy",10,IF(L19="Neutral",5,0))),0),"") | AB19: =IFERROR(IF(AA19>=80,"🔥 HOT",IF(AA19>=60,"✅ STRONG",IF(AA19>=40,"⚡ WARM",IF(AA19>=20,"📋 NURTURE",IF(AA19>0,"❌ COLD",""))))),"") | AC19: =IFERROR(IF(AND(AA19>=60,OR(W19="Yes",W19="Later")),"🚨 URGENT",IF(AND(AA19>=40,I19="Call Back"),"📞 CALL BACK",IF(I19="Booked Meeting","📅 BOOKED",IF(I19="Not Interested","🚫 DEAD","⏳ WORKING")))),"") | AD19: 04/16/2026@2:42pm | AE19: 46129 | AF19: =IFERROR(IF(AE19="","",AE19-TODAY()),"") | AG19: Kristopher
A20: Rocket HVAC | B20: (385)722-7638 | C20: West Jordan | D20: Click Here | E20: NA | F20: NA | G20: NA | H20: NA | I20: Answered | J20: NA | K20: No | L20: Hostile | M20: Operations/System | N20: The guy answered the phone, we talk for a little bit, I gave him my opener, and he seemed very curious. I ended up telling him what we do, and that's when I was like, all I need is just 15 minutes," and he said "We're super busy, we can't meet with you any time soon," and I'm not going to take that for a fucking answer, I was like, "Okay, well, good thing I only need 15 minutes," and as I Continued, he literally hung up. | O20: NA | Q20: Severe | R20: Severe | S20: Severe | T20: Moderate | U20: "We Are Super Busy" | V20: =IFERROR(ROUND((IF(Q20="Severe",4,IF(Q20="Moderate",3,IF(Q20="Minor",2,0)))+IF(R20="Severe",4,IF(R20="Moderate",3,IF(R20="Minor",2,0)))+IF(S20="Severe",4,IF(S20="Moderate",3,IF(S20="Minor",2,0)))+IF(T20="Severe",4,IF(T20="Moderate",3,IF(T20="Minor",2,0))))/16*100,0),"") | W20: Later | X20: None Yet | Y20: NA | Z20: Call Back | AA20: =IFERROR(ROUND(IF(H20>=10,30,IF(H20>=5,20,IF(H20>=2,10,0)))+IF(K20="Yes",20,IF(K20="Unsure",10,0))+IF(W20="Yes",30,IF(W20="Later",15,0))+IFERROR(V20/100*20,0)+IF(L20="Interested",15,IF(L20="Open But Busy",10,IF(L20="Neutral",5,0))),0),"") | AB20: =IFERROR(IF(AA20>=80,"🔥 HOT",IF(AA20>=60,"✅ STRONG",IF(AA20>=40,"⚡ WARM",IF(AA20>=20,"📋 NURTURE",IF(AA20>0,"❌ COLD",""))))),"") | AC20: =IFERROR(IF(AND(AA20>=60,OR(W20="Yes",W20="Later")),"🚨 URGENT",IF(AND(AA20>=40,I20="Call Back"),"📞 CALL BACK",IF(I20="Booked Meeting","📅 BOOKED",IF(I20="Not Interested","🚫 DEAD","⏳ WORKING")))),"") | AD20: 04/16/2026@2:45pm | AE20: 46129 | AF20: =IFERROR(IF(AE20="","",AE20-TODAY()),"") | AG20: Kristopher
A21: Just Right Plumbing Heating & Colling | B21: (801)302-1154 | C21: Salt Lake City | D21: Click Here | E21: NA | F21: NA | G21: Call Center | H21: NA | I21: Bad Number | J21: Call Center That Books Their Calls | K21: No | L21: Neutral | M21: Operations/System | N21: They are outsourcing their bookings to a call center, which I'm sure is costing them an arm and a leg. | O21: NA | Q21: Minor | R21: Moderate | S21: Severe | T21: Moderate | U21: She Said Just go there whats the worst they could say? | V21: =IFERROR(ROUND((IF(Q21="Severe",4,IF(Q21="Moderate",3,IF(Q21="Minor",2,0)))+IF(R21="Severe",4,IF(R21="Moderate",3,IF(R21="Minor",2,0)))+IF(S21="Severe",4,IF(S21="Moderate",3,IF(S21="Minor",2,0)))+IF(T21="Severe",4,IF(T21="Moderate",3,IF(T21="Minor",2,0))))/16*100,0),"") | W21: Later | X21: In Person | Y21: None really the call center told me to just go to the office | Z21: Book In Person | AA21: =IFERROR(ROUND(IF(H21>=10,30,IF(H21>=5,20,IF(H21>=2,10,0)))+IF(K21="Yes",20,IF(K21="Unsure",10,0))+IF(W21="Yes",30,IF(W21="Later",15,0))+IFERROR(V21/100*20,0)+IF(L21="Interested",15,IF(L21="Open But Busy",10,IF(L21="Neutral",5,0))),0),"") | AB21: =IFERROR(IF(AA21>=80,"🔥 HOT",IF(AA21>=60,"✅ STRONG",IF(AA21>=40,"⚡ WARM",IF(AA21>=20,"📋 NURTURE",IF(AA21>0,"❌ COLD",""))))),"") | AC21: =IFERROR(IF(AND(AA21>=60,OR(W21="Yes",W21="Later")),"🚨 URGENT",IF(AND(AA21>=40,I21="Call Back"),"📞 CALL BACK",IF(I21="Booked Meeting","📅 BOOKED",IF(I21="Not Interested","🚫 DEAD","⏳ WORKING")))),"") | AD21: 04/17/2026@9:23am | AE21: 46129 | AF21: =IFERROR(IF(AE21="","",AE21-TODAY()),"") | AG21: Kristopher
A22: A-1 Heating & Colling | B22: (801)210-1018 | C22: Murray | D22: Click Here | E22: Asim | F22: a1heatingandcooling@gmail.com | G22: Owner | H22: 5+ | I22: Answered | J22: Owner | K22: Yes | L22: Interested | M22: Operations/System | N22: They are extremely busy today, but he said Monday morning at 10:30AM will be perfect. | O22: NA | Q22: Moderate | R22: Moderate | S22: Severe | T22: Moderate | U22: He was just extremely busy, and it's clear they don't have a system because he was the one answering the phone, and when he answered the phone, he seemed very agitated. | V22: =IFERROR(ROUND((IF(Q22="Severe",4,IF(Q22="Moderate",3,IF(Q22="Minor",2,0)))+IF(R22="Severe",4,IF(R22="Moderate",3,IF(R22="Minor",2,0)))+IF(S22="Severe",4,IF(S22="Moderate",3,IF(S22="Minor",2,0)))+IF(T22="Severe",4,IF(T22="Moderate",3,IF(T22="Minor",2,0))))/16*100,0),"") | W22: Yes | X22: In Person | Y22: He really didn't have any objections, he just seems very open to talking about his business. | Z22: Book In Person | AA22: =IFERROR(ROUND(IF(H22>=10,30,IF(H22>=5,20,IF(H22>=2,10,0)))+IF(K22="Yes",20,IF(K22="Unsure",10,0))+IF(W22="Yes",30,IF(W22="Later",15,0))+IFERROR(V22/100*20,0)+IF(L22="Interested",15,IF(L22="Open But Busy",10,IF(L22="Neutral",5,0))),0),"") | AB22: =IFERROR(IF(AA22>=80,"🔥 HOT",IF(AA22>=60,"✅ STRONG",IF(AA22>=40,"⚡ WARM",IF(AA22>=20,"📋 NURTURE",IF(AA22>0,"❌ COLD",""))))),"") | AC22: =IFERROR(IF(AND(AA22>=60,OR(W22="Yes",W22="Later")),"🚨 URGENT",IF(AND(AA22>=40,I22="Call Back"),"📞 CALL BACK",IF(I22="Booked Meeting","📅 BOOKED",IF(I22="Not Interested","🚫 DEAD","⏳ WORKING")))),"") | AD22: 04/17/2026@9:29am | AE22: 46132 | AF22: =IFERROR(IF(AE22="","",AE22-TODAY()),"") | AG22: Kristopher
A23: Scott Hale Plumbing Heating & Air | B23: (801)312-9038 | C23: Murray | D23: Click Here | E23: NA | F23: NA | G23: CSR | H23: 20+ | I23: Answered | J23: CST/Kashai | K23: No | L23: Open But Busy | M23: Operations/System | N23: Honestly, I could not get past the gatekeeper, as I was talking about how I want to bring coffee and donuts for the install crew, and take a moment or two with the owner, she seemed very surprised, and was like, "What company are you with?" and I ended up telling her where with Econ Growth, and what we do is we install AI infrastructure to increase business valuation. Now, I just want to have a quick moment with the owner, because I want to show him something that I built, and she was like, "Okay, let me take down your name, your number, and a little bit of information, and I'll give it to a manager and I'll have them call you back, if they're interested." | O23: NA | Q23: Minor | R23: Minor | S23: Severe | T23: Moderate | U23: This one was on me — I could not get past the gatekeeper, and I knew I should have asked better questions instead of just answering the questions, but only on my third call for the day, Not bad. | V23: =IFERROR(ROUND((IF(Q23="Severe",4,IF(Q23="Moderate",3,IF(Q23="Minor",2,0)))+IF(R23="Severe",4,IF(R23="Moderate",3,IF(R23="Minor",2,0)))+IF(S23="Severe",4,IF(S23="Moderate",3,IF(S23="Minor",2,0)))+IF(T23="Severe",4,IF(T23="Moderate",3,IF(T23="Minor",2,0))))/16*100,0),"") | W23: Later | X23: None Yet | Y23: No real objections — they were just more curious about who I was and what I wanted, which after I shared about increasing business valuation via AI infrastructure and us working with a select few individuals who have the right expertise in the space to be able to scale over $150 million in revenue. | Z23: Call Back | AA23: =IFERROR(ROUND(IF(H23>=10,30,IF(H23>=5,20,IF(H23>=2,10,0)))+IF(K23="Yes",20,IF(K23="Unsure",10,0))+IF(W23="Yes",30,IF(W23="Later",15,0))+IFERROR(V23/100*20,0)+IF(L23="Interested",15,IF(L23="Open But Busy",10,IF(L23="Neutral",5,0))),0),"") | AB23: =IFERROR(IF(AA23>=80,"🔥 HOT",IF(AA23>=60,"✅ STRONG",IF(AA23>=40,"⚡ WARM",IF(AA23>=20,"📋 NURTURE",IF(AA23>0,"❌ COLD",""))))),"") | AC23: =IFERROR(IF(AND(AA23>=60,OR(W23="Yes",W23="Later")),"🚨 URGENT",IF(AND(AA23>=40,I23="Call Back"),"📞 CALL BACK",IF(I23="Booked Meeting","📅 BOOKED",IF(I23="Not Interested","🚫 DEAD","⏳ WORKING")))),"") | AD23: 04/17/2026@9:56am | AE23: 46132 | AF23: =IFERROR(IF(AE23="","",AE23-TODAY()),"") | AG23: Kristopher
A24: Air Design Heating & Cooling | B24: (385)332-8200 | C24: Murray | D24: Click Here | E24: NA | F24: NA | G24: CSR | H24: 10+ | I24: Answered | J24: Lance | K24: No | L24: Interested | M24: Operations/System | N24: This one went way better than I expected. I actually had more of a conversation with the CSR's, and I'm getting to a point where I'm getting the CSRs very interested. I just want to figure out now how I can get them from interested to "Holy shit, let me just patch you over right now!" This seems really important. | O24: NA | Q24: Moderate | R24: Moderate | S24: Severe | T24: Moderate | U24: You see, this one, I'm getting better with the company paying none, really, except none that I could see, and that's probably because after he told me that he had an AI already, I kinda just diverted from trying to sell the AI robot, to talking about how we install AI infrastructure to increase business valuation at a 7x to 8x EBITDA earnings, and after I did that, he seemed extremely interested and was like, "All right, let me take down your information, and I will just have the owner call you." | V24: =IFERROR(ROUND((IF(Q24="Severe",4,IF(Q24="Moderate",3,IF(Q24="Minor",2,0)))+IF(R24="Severe",4,IF(R24="Moderate",3,IF(R24="Minor",2,0)))+IF(S24="Severe",4,IF(S24="Moderate",3,IF(S24="Minor",2,0)))+IF(T24="Severe",4,IF(T24="Moderate",3,IF(T24="Minor",2,0))))/16*100,0),"") | W24: Later | X24: None Yet | Y24: I choked up instead of asking more clarifying questions about what their AI does. I converted over into how we install AI infrastructure to increase business valuation. I could have done better on asking questions to see if Roger can compete with their AI that they have, or if their AI is literally just basic conversation having from GHL, or something. | Z24: Call Back | AA24: =IFERROR(ROUND(IF(H24>=10,30,IF(H24>=5,20,IF(H24>=2,10,0)))+IF(K24="Yes",20,IF(K24="Unsure",10,0))+IF(W24="Yes",30,IF(W24="Later",15,0))+IFERROR(V24/100*20,0)+IF(L24="Interested",15,IF(L24="Open But Busy",10,IF(L24="Neutral",5,0))),0),"") | AB24: =IFERROR(IF(AA24>=80,"🔥 HOT",IF(AA24>=60,"✅ STRONG",IF(AA24>=40,"⚡ WARM",IF(AA24>=20,"📋 NURTURE",IF(AA24>0,"❌ COLD",""))))),"") | AC24: =IFERROR(IF(AND(AA24>=60,OR(W24="Yes",W24="Later")),"🚨 URGENT",IF(AND(AA24>=40,I24="Call Back"),"📞 CALL BACK",IF(I24="Booked Meeting","📅 BOOKED",IF(I24="Not Interested","🚫 DEAD","⏳ WORKING")))),"") | AD24: 04/17/2026@10:11am | AE24: 46132 | AF24: =IFERROR(IF(AE24="","",AE24-TODAY()),"") | AG24: Kristopher
A25: Home Performance Pros | B25: (385)503-7767 | C25: Murray | D25: Click Here | E25: NA | F25: NA | G25: CSR | H25: NA | I25: Answered | J25: Jared | K25: No | L25: Hostile | M25: Training | N25: So a guy named Jared answered the phone, hit them with my opener, coffee and doughnuts, and he's like, "Well, absolutely, what's this regarding?" And that's when I told him, "Well, Jared, let me ask you a quick question: when a call comes in at 10:00 PM, what happens?" And he hung up on me, and so, me, being me, I called back, went straight to their AI, and their AI is pretty freaking dope. Not gonna lie. | O25: NA | Q25: Moderate | R25: Moderate | S25: Minor | T25: Moderate | U25: First thing I'd have to say is their training for their team has to be garbage because what business owner has taught their CSRs to just hang up the phone | V25: =IFERROR(ROUND((IF(Q25="Severe",4,IF(Q25="Moderate",3,IF(Q25="Minor",2,0)))+IF(R25="Severe",4,IF(R25="Moderate",3,IF(R25="Minor",2,0)))+IF(S25="Severe",4,IF(S25="Moderate",3,IF(S25="Minor",2,0)))+IF(T25="Severe",4,IF(T25="Moderate",3,IF(T25="Minor",2,0))))/16*100,0),"") | W25: Later | X25: None Yet | Y25: Well, in the conversation that we had, really, was just one-sided, mostly my part, as I kept talking, and he just hung up. But what blows my mind is because with everybody else, I just kept talking, they stayed on the phone, so I think honestly, he just really didn't know what he was supposed to do. | Z25: Call Back | AA25: =IFERROR(ROUND(IF(H25>=10,30,IF(H25>=5,20,IF(H25>=2,10,0)))+IF(K25="Yes",20,IF(K25="Unsure",10,0))+IF(W25="Yes",30,IF(W25="Later",15,0))+IFERROR(V25/100*20,0)+IF(L25="Interested",15,IF(L25="Open But Busy",10,IF(L25="Neutral",5,0))),0),"") | AB25: =IFERROR(IF(AA25>=80,"🔥 HOT",IF(AA25>=60,"✅ STRONG",IF(AA25>=40,"⚡ WARM",IF(AA25>=20,"📋 NURTURE",IF(AA25>0,"❌ COLD",""))))),"") | AC25: =IFERROR(IF(AND(AA25>=60,OR(W25="Yes",W25="Later")),"🚨 URGENT",IF(AND(AA25>=40,I25="Call Back"),"📞 CALL BACK",IF(I25="Booked Meeting","📅 BOOKED",IF(I25="Not Interested","🚫 DEAD","⏳ WORKING")))),"") | AD25: 04/17/2026@10:30am | AF25: =IFERROR(IF(AE25="","",AE25-TODAY()),"") | AG25: Kristopher
A26: Apex Clean Air AC & Heating Repair | B26: (801)396-8959 | C26: Salt Lake City | D26: Click Here | E26: Mike | F26: utah@apexcleanair.com | G26: CSR | H26: NA | I26: Answered | J26: Breanne | K26: Yes | L26: Interested | M26: Scheduling | N26: So I just talked to Brianne, and she said that she doesn't really know the owner's schedule, which honestly makes sense, because if she's the CSS, you know, I'd like to really be able to get over that objection, because it's something like that, I mean, what the fuck do you say to that? Oh, okay, well, all I really need is 15 minutes, is he nearby? I don't even know what the hell to say to that, so I was just like, "Okay, yeah," what's his email, what's his name, what's your name? And that's where we're at. | O26: NA | Q26: Moderate | R26: Moderate | S26: Severe | T26: Moderate | U26: The first thing I noticed was that they have an old legacy system that says press 1 to be connected to HVAC, press 2 to be connected to plumbing, so press 0 if you're unsure. That's old as fuck, outdated, they need a roger. | V26: =IFERROR(ROUND((IF(Q26="Severe",4,IF(Q26="Moderate",3,IF(Q26="Minor",2,0)))+IF(R26="Severe",4,IF(R26="Moderate",3,IF(R26="Minor",2,0)))+IF(S26="Severe",4,IF(S26="Moderate",3,IF(S26="Minor",2,0)))+IF(T26="Severe",4,IF(T26="Moderate",3,IF(T26="Minor",2,0))))/16*100,0),"") | W26: Later | X26: None Yet | Y26: The first thing I noticed was that they have an old legacy system that says press 1 to be connected to HVAC, press 2 to be connected to plumbing, so press 0 if you're unsure. That's old as fuck, outdated, they need a roger. | Z26: Call Back | AA26: =IFERROR(ROUND(IF(H26>=10,30,IF(H26>=5,20,IF(H26>=2,10,0)))+IF(K26="Yes",20,IF(K26="Unsure",10,0))+IF(W26="Yes",30,IF(W26="Later",15,0))+IFERROR(V26/100*20,0)+IF(L26="Interested",15,IF(L26="Open But Busy",10,IF(L26="Neutral",5,0))),0),"") | AB26: =IFERROR(IF(AA26>=80,"🔥 HOT",IF(AA26>=60,"✅ STRONG",IF(AA26>=40,"⚡ WARM",IF(AA26>=20,"📋 NURTURE",IF(AA26>0,"❌ COLD",""))))),"") | AC26: =IFERROR(IF(AND(AA26>=60,OR(W26="Yes",W26="Later")),"🚨 URGENT",IF(AND(AA26>=40,I26="Call Back"),"📞 CALL BACK",IF(I26="Booked Meeting","📅 BOOKED",IF(I26="Not Interested","🚫 DEAD","⏳ WORKING")))),"") | AD26: 04/17/2026@10:39am | AF26: =IFERROR(IF(AE26="","",AE26-TODAY()),"") | AG26: Kristopher
A27: Manwill Plumbing Heating & Air | B27: (801)262-4671 | C27: Salt Lake City | D27: Click Here | E27: Bryan | F27: JBJackson@Manwillhvac.com | G27: Installer | H27: NA | I27: Answered | J27: Jessie | K27: Yes | L27: Open But Busy | M27: Operations/System | N27: So I spoke to Jessie, and he was like, "Right after I hit him with that opener, well, man, thank you so much, that's awesome of you." By the way, who am I even talking to? And then you know, we got bullshitting, and I found out he was an installer, and I've been doing it for like 30 years, and way too damn long is what I said, and we laughed. And from there, we went into, and he's like, "I can just send you to his voicemail if you want," and then I was like, "That'd be perfect." Also, man, while I got you on the phone, let me ask you real quick, what actually happens to a call that comes in after 10 o'clock at night? And Jessie said, "Well, it goes to our call center, and from the call center, they put it on our technicians' calendars and stuff," which I'm assuming is expensive AF. Roger, already can cut the cost of that tremendously, and guess what, it's all in house, | O27: NA | Q27: Minor | R27: None | S27: Severe | T27: Minor | U27: No Ai and Outsourcing after Hour calls to a call center | V27: =IFERROR(ROUND((IF(Q27="Severe",4,IF(Q27="Moderate",3,IF(Q27="Minor",2,0)))+IF(R27="Severe",4,IF(R27="Moderate",3,IF(R27="Minor",2,0)))+IF(S27="Severe",4,IF(S27="Moderate",3,IF(S27="Minor",2,0)))+IF(T27="Severe",4,IF(T27="Moderate",3,IF(T27="Minor",2,0))))/16*100,0),"") | W27: Later | X27: None Yet | Y27: None patched me to owner and we were crackin up laughin | Z27: Call Back | AA27: =IFERROR(ROUND(IF(H27>=10,30,IF(H27>=5,20,IF(H27>=2,10,0)))+IF(K27="Yes",20,IF(K27="Unsure",10,0))+IF(W27="Yes",30,IF(W27="Later",15,0))+IFERROR(V27/100*20,0)+IF(L27="Interested",15,IF(L27="Open But Busy",10,IF(L27="Neutral",5,0))),0),"") | AB27: =IFERROR(IF(AA27>=80,"🔥 HOT",IF(AA27>=60,"✅ STRONG",IF(AA27>=40,"⚡ WARM",IF(AA27>=20,"📋 NURTURE",IF(AA27>0,"❌ COLD",""))))),"") | AC27: =IFERROR(IF(AND(AA27>=60,OR(W27="Yes",W27="Later")),"🚨 URGENT",IF(AND(AA27>=40,I27="Call Back"),"📞 CALL BACK",IF(I27="Booked Meeting","📅 BOOKED",IF(I27="Not Interested","🚫 DEAD","⏳ WORKING")))),"") | AD27: 04/17/2026@10:45am | AF27: =IFERROR(IF(AE27="","",AE27-TODAY()),"") | AG27: Kristopher
A28: Affordable Heating & Cooling | B28: (801)261-0924 | C28: Salt Lake City | D28: Click Here | E28: NA | F28: NA | G28: CSR | H28: NA | I28: Answered | J28: Savannah | K28: No | L28: Not Interested | M28: No Clear Pain Point | N28: Definitely messed up on that one — said "Wasatch County" when I meant to say "Wasatch Front". Don't know why I did that, but I did it | O28: affodable Heating & Air Cold Call.m4a | P28: affodable Heating & Air Cold Call.docx | Q28: Minor | R28: Minor | S28: Severe | T28: Minor | U28: My words got mixxed | V28: =IFERROR(ROUND((IF(Q28="Severe",4,IF(Q28="Moderate",3,IF(Q28="Minor",2,0)))+IF(R28="Severe",4,IF(R28="Moderate",3,IF(R28="Minor",2,0)))+IF(S28="Severe",4,IF(S28="Moderate",3,IF(S28="Minor",2,0)))+IF(T28="Severe",4,IF(T28="Moderate",3,IF(T28="Minor",2,0))))/16*100,0),"") | W28: No | X28: None Yet | Y28: Not interested | Z28: Call Back | AA28: =IFERROR(ROUND(IF(H28>=10,30,IF(H28>=5,20,IF(H28>=2,10,0)))+IF(K28="Yes",20,IF(K28="Unsure",10,0))+IF(W28="Yes",30,IF(W28="Later",15,0))+IFERROR(V28/100*20,0)+IF(L28="Interested",15,IF(L28="Open But Busy",10,IF(L28="Neutral",5,0))),0),"") | AB28: =IFERROR(IF(AA28>=80,"🔥 HOT",IF(AA28>=60,"✅ STRONG",IF(AA28>=40,"⚡ WARM",IF(AA28>=20,"📋 NURTURE",IF(AA28>0,"❌ COLD",""))))),"") | AC28: =IFERROR(IF(AND(AA28>=60,OR(W28="Yes",W28="Later")),"🚨 URGENT",IF(AND(AA28>=40,I28="Call Back"),"📞 CALL BACK",IF(I28="Booked Meeting","📅 BOOKED",IF(I28="Not Interested","🚫 DEAD","⏳ WORKING")))),"") | AD28: 04/17/2026@11:47am | AF28: =IFERROR(IF(AE28="","",AE28-TODAY()),"") | AG28: Kristopher
A29: I Know A Guy HVAC | B29: (385)455-4700 | C29: Salt Lake City | D29: Click Here | E29: Brandon & Dustin | F29: NA | G29: CSR | H29: NA | I29: Answered | J29: Shey | K29: No | L29: Open But Busy | M29: Operations/System | N29: Well I knew that Gal Because I used to work there and also her Boyfriend and i used to hang out together | O29: NA | P29: NA | Q29: Severe | R29: Severe | S29: Severe | T29: Moderate | U29: Well I know these guys used to work there they have no system in place Communication is a joke and they want retrofits but mostly do New Construction | V29: =IFERROR(ROUND((IF(Q29="Severe",4,IF(Q29="Moderate",3,IF(Q29="Minor",2,0)))+IF(R29="Severe",4,IF(R29="Moderate",3,IF(R29="Minor",2,0)))+IF(S29="Severe",4,IF(S29="Moderate",3,IF(S29="Minor",2,0)))+IF(T29="Severe",4,IF(T29="Moderate",3,IF(T29="Minor",2,0))))/16*100,0),"") | W29: Later | X29: None Yet | Y29: None they wanted to know how I was Doing | Z29: Call Back | AA29: =IFERROR(ROUND(IF(H29>=10,30,IF(H29>=5,20,IF(H29>=2,10,0)))+IF(K29="Yes",20,IF(K29="Unsure",10,0))+IF(W29="Yes",30,IF(W29="Later",15,0))+IFERROR(V29/100*20,0)+IF(L29="Interested",15,IF(L29="Open But Busy",10,IF(L29="Neutral",5,0))),0),"") | AB29: =IFERROR(IF(AA29>=80,"🔥 HOT",IF(AA29>=60,"✅ STRONG",IF(AA29>=40,"⚡ WARM",IF(AA29>=20,"📋 NURTURE",IF(AA29>0,"❌ COLD",""))))),"") | AC29: =IFERROR(IF(AND(AA29>=60,OR(W29="Yes",W29="Later")),"🚨 URGENT",IF(AND(AA29>=40,I29="Call Back"),"📞 CALL BACK",IF(I29="Booked Meeting","📅 BOOKED",IF(I29="Not Interested","🚫 DEAD","⏳ WORKING")))),"") | AD29: 04/17/2026@12:09pm | AF29: =IFERROR(IF(AE29="","",AE29-TODAY()),"") | AG29: Kristopher
A30: SOS Heating & Cooling | B30: (801)890-3577 | C30: Salt Lake City | D30: Click Here | E30: Greyson & Jason | F30: NA | G30: CSR | H30: NA | I30: Answered | J30: Ashley | K30: No | L30: Interested | M30: Operations/System | O30: S.O.S Heating & Cooling.m4a | P30: S.O.S Heating & Cooling.docx | V30: =IFERROR(ROUND((IF(Q30="Severe",4,IF(Q30="Moderate",3,IF(Q30="Minor",2,0)))+IF(R30="Severe",4,IF(R30="Moderate",3,IF(R30="Minor",2,0)))+IF(S30="Severe",4,IF(S30="Moderate",3,IF(S30="Minor",2,0)))+IF(T30="Severe",4,IF(T30="Moderate",3,IF(T30="Minor",2,0))))/16*100,0),"") | AA30: =IFERROR(ROUND(IF(H30>=10,30,IF(H30>=5,20,IF(H30>=2,10,0)))+IF(K30="Yes",20,IF(K30="Unsure",10,0))+IF(W30="Yes",30,IF(W30="Later",15,0))+IFERROR(V30/100*20,0)+IF(L30="Interested",15,IF(L30="Open But Busy",10,IF(L30="Neutral",5,0))),0),"") | AB30: =IFERROR(IF(AA30>=80,"🔥 HOT",IF(AA30>=60,"✅ STRONG",IF(AA30>=40,"⚡ WARM",IF(AA30>=20,"📋 NURTURE",IF(AA30>0,"❌ COLD",""))))),"") | AC30: =IFERROR(IF(AND(AA30>=60,OR(W30="Yes",W30="Later")),"🚨 URGENT",IF(AND(AA30>=40,I30="Call Back"),"📞 CALL BACK",IF(I30="Booked Meeting","📅 BOOKED",IF(I30="Not Interested","🚫 DEAD","⏳ WORKING")))),"") | AF30: =IFERROR(IF(AE30="","",AE30-TODAY()),"") | AG30: Kristopher
A31: Bee Hive Heating & Air | B31: (801)618-1195 | C31: Salt Lake City | D31: Click Here | E31: NA | F31: NA | G31: CCR | H31: NA | I31: Answered | J31: Logan | K31: No | L31: Neutral | M31: Operations/System | N31: Call Center Picked up | O31: Beehive Plumbing HVAC.m4a | P31: Beehive Plumbing HVAC.docx | V31: =IFERROR(ROUND((IF(Q31="Severe",4,IF(Q31="Moderate",3,IF(Q31="Minor",2,0)))+IF(R31="Severe",4,IF(R31="Moderate",3,IF(R31="Minor",2,0)))+IF(S31="Severe",4,IF(S31="Moderate",3,IF(S31="Minor",2,0)))+IF(T31="Severe",4,IF(T31="Moderate",3,IF(T31="Minor",2,0))))/16*100,0),"") | AA31: =IFERROR(ROUND(IF(H31>=10,30,IF(H31>=5,20,IF(H31>=2,10,0)))+IF(K31="Yes",20,IF(K31="Unsure",10,0))+IF(W31="Yes",30,IF(W31="Later",15,0))+IFERROR(V31/100*20,0)+IF(L31="Interested",15,IF(L31="Open But Busy",10,IF(L31="Neutral",5,0))),0),"") | AB31: =IFERROR(IF(AA31>=80,"🔥 HOT",IF(AA31>=60,"✅ STRONG",IF(AA31>=40,"⚡ WARM",IF(AA31>=20,"📋 NURTURE",IF(AA31>0,"❌ COLD",""))))),"") | AC31: =IFERROR(IF(AND(AA31>=60,OR(W31="Yes",W31="Later")),"🚨 URGENT",IF(AND(AA31>=40,I31="Call Back"),"📞 CALL BACK",IF(I31="Booked Meeting","📅 BOOKED",IF(I31="Not Interested","🚫 DEAD","⏳ WORKING")))),"") | AF31: =IFERROR(IF(AE31="","",AE31-TODAY()),"") | AG31: Kristopher
A32: Jones Heating & Air | B32: (801)972-8557 | C32: West Valley City | D32: Click Here | E32: Djon | F32: NA | G32: CSR | H32: NA | I32: Answered | J32: Christine | K32: No | L32: Open But Busy | M32: Operations/System | N32: Owner out of town and will be back next week | O32: Jones Heating & Air.m4a | P32: Jones Heating & Air.docx | V32: =IFERROR(ROUND((IF(Q32="Severe",4,IF(Q32="Moderate",3,IF(Q32="Minor",2,0)))+IF(R32="Severe",4,IF(R32="Moderate",3,IF(R32="Minor",2,0)))+IF(S32="Severe",4,IF(S32="Moderate",3,IF(S32="Minor",2,0)))+IF(T32="Severe",4,IF(T32="Moderate",3,IF(T32="Minor",2,0))))/16*100,0),"") | AA32: =IFERROR(ROUND(IF(H32>=10,30,IF(H32>=5,20,IF(H32>=2,10,0)))+IF(K32="Yes",20,IF(K32="Unsure",10,0))+IF(W32="Yes",30,IF(W32="Later",15,0))+IFERROR(V32/100*20,0)+IF(L32="Interested",15,IF(L32="Open But Busy",10,IF(L32="Neutral",5,0))),0),"") | AB32: =IFERROR(IF(AA32>=80,"🔥 HOT",IF(AA32>=60,"✅ STRONG",IF(AA32>=40,"⚡ WARM",IF(AA32>=20,"📋 NURTURE",IF(AA32>0,"❌ COLD",""))))),"") | AC32: =IFERROR(IF(AND(AA32>=60,OR(W32="Yes",W32="Later")),"🚨 URGENT",IF(AND(AA32>=40,I32="Call Back"),"📞 CALL BACK",IF(I32="Booked Meeting","📅 BOOKED",IF(I32="Not Interested","🚫 DEAD","⏳ WORKING")))),"") | AF32: =IFERROR(IF(AE32="","",AE32-TODAY()),"") | AG32: Kristopher
A33: Same Day Heating & Air | B33: (801)297-1654 | C33: Salt Lake City | D33: Click Here | E33: NA | F33: NA | G33: CSR | H33: NA | I33: Answered | J33: Robert | K33: No | L33: Open But Busy | M33: Operations/System | N33: Scheduled for monday | O33: Whipple Service Champions.m4a | P33: Whipple Service Champions.docx | V33: =IFERROR(ROUND((IF(Q33="Severe",4,IF(Q33="Moderate",3,IF(Q33="Minor",2,0)))+IF(R33="Severe",4,IF(R33="Moderate",3,IF(R33="Minor",2,0)))+IF(S33="Severe",4,IF(S33="Moderate",3,IF(S33="Minor",2,0)))+IF(T33="Severe",4,IF(T33="Moderate",3,IF(T33="Minor",2,0))))/16*100,0),"") | AA33: =IFERROR(ROUND(IF(H33>=10,30,IF(H33>=5,20,IF(H33>=2,10,0)))+IF(K33="Yes",20,IF(K33="Unsure",10,0))+IF(W33="Yes",30,IF(W33="Later",15,0))+IFERROR(V33/100*20,0)+IF(L33="Interested",15,IF(L33="Open But Busy",10,IF(L33="Neutral",5,0))),0),"") | AB33: =IFERROR(IF(AA33>=80,"🔥 HOT",IF(AA33>=60,"✅ STRONG",IF(AA33>=40,"⚡ WARM",IF(AA33>=20,"📋 NURTURE",IF(AA33>0,"❌ COLD",""))))),"") | AC33: =IFERROR(IF(AND(AA33>=60,OR(W33="Yes",W33="Later")),"🚨 URGENT",IF(AND(AA33>=40,I33="Call Back"),"📞 CALL BACK",IF(I33="Booked Meeting","📅 BOOKED",IF(I33="Not Interested","🚫 DEAD","⏳ WORKING")))),"") | AF33: =IFERROR(IF(AE33="","",AE33-TODAY()),"") | AG33: Kristopher
A34: Whipple Service Champions | B34: (801)214-1515 | C34: West Valley City | D34: Click Here | E34: NA | F34: NA | G34: Manager | H34: NA | I34: Answered | J34: Lester Acola | V34: =IFERROR(ROUND((IF(Q34="Severe",4,IF(Q34="Moderate",3,IF(Q34="Minor",2,0)))+IF(R34="Severe",4,IF(R34="Moderate",3,IF(R34="Minor",2,0)))+IF(S34="Severe",4,IF(S34="Moderate",3,IF(S34="Minor",2,0)))+IF(T34="Severe",4,IF(T34="Moderate",3,IF(T34="Minor",2,0))))/16*100,0),"") | AA34: =IFERROR(ROUND(IF(H34>=10,30,IF(H34>=5,20,IF(H34>=2,10,0)))+IF(K34="Yes",20,IF(K34="Unsure",10,0))+IF(W34="Yes",30,IF(W34="Later",15,0))+IFERROR(V34/100*20,0)+IF(L34="Interested",15,IF(L34="Open But Busy",10,IF(L34="Neutral",5,0))),0),"") | AB34: =IFERROR(IF(AA34>=80,"🔥 HOT",IF(AA34>=60,"✅ STRONG",IF(AA34>=40,"⚡ WARM",IF(AA34>=20,"📋 NURTURE",IF(AA34>0,"❌ COLD",""))))),"") | AC34: =IFERROR(IF(AND(AA34>=60,OR(W34="Yes",W34="Later")),"🚨 URGENT",IF(AND(AA34>=40,I34="Call Back"),"📞 CALL BACK",IF(I34="Booked Meeting","📅 BOOKED",IF(I34="Not Interested","🚫 DEAD","⏳ WORKING")))),"") | AF34: =IFERROR(IF(AE34="","",AE34-TODAY()),"") | AG34: Kristopher
A35: Select Comfort Systems | B35: (801)969-7088 | C35: West Valley City | D35: Click Here | E35: NA | F35: NA | G35: Office Manager/Owners Wife | H35: 2 | I35: Answered | J35: Lisa B. | V35: =IFERROR(ROUND((IF(Q35="Severe",4,IF(Q35="Moderate",3,IF(Q35="Minor",2,0)))+IF(R35="Severe",4,IF(R35="Moderate",3,IF(R35="Minor",2,0)))+IF(S35="Severe",4,IF(S35="Moderate",3,IF(S35="Minor",2,0)))+IF(T35="Severe",4,IF(T35="Moderate",3,IF(T35="Minor",2,0))))/16*100,0),"") | AA35: =IFERROR(ROUND(IF(H35>=10,30,IF(H35>=5,20,IF(H35>=2,10,0)))+IF(K35="Yes",20,IF(K35="Unsure",10,0))+IF(W35="Yes",30,IF(W35="Later",15,0))+IFERROR(V35/100*20,0)+IF(L35="Interested",15,IF(L35="Open But Busy",10,IF(L35="Neutral",5,0))),0),"") | AB35: =IFERROR(IF(AA35>=80,"🔥 HOT",IF(AA35>=60,"✅ STRONG",IF(AA35>=40,"⚡ WARM",IF(AA35>=20,"📋 NURTURE",IF(AA35>0,"❌ COLD",""))))),"") | AC35: =IFERROR(IF(AND(AA35>=60,OR(W35="Yes",W35="Later")),"🚨 URGENT",IF(AND(AA35>=40,I35="Call Back"),"📞 CALL BACK",IF(I35="Booked Meeting","📅 BOOKED",IF(I35="Not Interested","🚫 DEAD","⏳ WORKING")))),"") | AF35: =IFERROR(IF(AE35="","",AE35-TODAY()),"") | AG35: Kristopher
A36: Perform Plumbing Heating & Air | B36: (385)330-2720 | C36: West Valley City | D36: Click Here | E36: NA | F36: Performhac@AskNpartners.com | H36: NA | I36: Answered | J36: NA | V36: =IFERROR(ROUND((IF(Q36="Severe",4,IF(Q36="Moderate",3,IF(Q36="Minor",2,0)))+IF(R36="Severe",4,IF(R36="Moderate",3,IF(R36="Minor",2,0)))+IF(S36="Severe",4,IF(S36="Moderate",3,IF(S36="Minor",2,0)))+IF(T36="Severe",4,IF(T36="Moderate",3,IF(T36="Minor",2,0))))/16*100,0),"") | AA36: =IFERROR(ROUND(IF(H36>=10,30,IF(H36>=5,20,IF(H36>=2,10,0)))+IF(K36="Yes",20,IF(K36="Unsure",10,0))+IF(W36="Yes",30,IF(W36="Later",15,0))+IFERROR(V36/100*20,0)+IF(L36="Interested",15,IF(L36="Open But Busy",10,IF(L36="Neutral",5,0))),0),"") | AB36: =IFERROR(IF(AA36>=80,"🔥 HOT",IF(AA36>=60,"✅ STRONG",IF(AA36>=40,"⚡ WARM",IF(AA36>=20,"📋 NURTURE",IF(AA36>0,"❌ COLD",""))))),"") | AC36: =IFERROR(IF(AND(AA36>=60,OR(W36="Yes",W36="Later")),"🚨 URGENT",IF(AND(AA36>=40,I36="Call Back"),"📞 CALL BACK",IF(I36="Booked Meeting","📅 BOOKED",IF(I36="Not Interested","🚫 DEAD","⏳ WORKING")))),"") | AF36: =IFERROR(IF(AE36="","",AE36-TODAY()),"") | AG36: Kristopher
A37: Mace Heating & Air | B37: (801)654-0273 | C37: Taylorsville | D37: Click Here | E37: NA | F37: NA | G37: Owner | H37: NA | I37: Answered | J37: Sean | V37: =IFERROR(ROUND((IF(Q37="Severe",4,IF(Q37="Moderate",3,IF(Q37="Minor",2,0)))+IF(R37="Severe",4,IF(R37="Moderate",3,IF(R37="Minor",2,0)))+IF(S37="Severe",4,IF(S37="Moderate",3,IF(S37="Minor",2,0)))+IF(T37="Severe",4,IF(T37="Moderate",3,IF(T37="Minor",2,0))))/16*100,0),"") | AA37: =IFERROR(ROUND(IF(H37>=10,30,IF(H37>=5,20,IF(H37>=2,10,0)))+IF(K37="Yes",20,IF(K37="Unsure",10,0))+IF(W37="Yes",30,IF(W37="Later",15,0))+IFERROR(V37/100*20,0)+IF(L37="Interested",15,IF(L37="Open But Busy",10,IF(L37="Neutral",5,0))),0),"") | AB37: =IFERROR(IF(AA37>=80,"🔥 HOT",IF(AA37>=60,"✅ STRONG",IF(AA37>=40,"⚡ WARM",IF(AA37>=20,"📋 NURTURE",IF(AA37>0,"❌ COLD",""))))),"") | AC37: =IFERROR(IF(AND(AA37>=60,OR(W37="Yes",W37="Later")),"🚨 URGENT",IF(AND(AA37>=40,I37="Call Back"),"📞 CALL BACK",IF(I37="Booked Meeting","📅 BOOKED",IF(I37="Not Interested","🚫 DEAD","⏳ WORKING")))),"") | AF37: =IFERROR(IF(AE37="","",AE37-TODAY()),"") | AG37: Kristopher
A38: Superior Water & Air | B38: (801)438-4795 | C38: Salt Lake City | D38: Click Here | E38: Superior Tem | F38: contact@superiorwaterandair | G38: CSR | H38: 19 | I38: Answered | J38: Isac | V38: =IFERROR(ROUND((IF(Q38="Severe",4,IF(Q38="Moderate",3,IF(Q38="Minor",2,0)))+IF(R38="Severe",4,IF(R38="Moderate",3,IF(R38="Minor",2,0)))+IF(S38="Severe",4,IF(S38="Moderate",3,IF(S38="Minor",2,0)))+IF(T38="Severe",4,IF(T38="Moderate",3,IF(T38="Minor",2,0))))/16*100,0),"") | AA38: =IFERROR(ROUND(IF(H38>=10,30,IF(H38>=5,20,IF(H38>=2,10,0)))+IF(K38="Yes",20,IF(K38="Unsure",10,0))+IF(W38="Yes",30,IF(W38="Later",15,0))+IFERROR(V38/100*20,0)+IF(L38="Interested",15,IF(L38="Open But Busy",10,IF(L38="Neutral",5,0))),0),"") | AB38: =IFERROR(IF(AA38>=80,"🔥 HOT",IF(AA38>=60,"✅ STRONG",IF(AA38>=40,"⚡ WARM",IF(AA38>=20,"📋 NURTURE",IF(AA38>0,"❌ COLD",""))))),"") | AC38: =IFERROR(IF(AND(AA38>=60,OR(W38="Yes",W38="Later")),"🚨 URGENT",IF(AND(AA38>=40,I38="Call Back"),"📞 CALL BACK",IF(I38="Booked Meeting","📅 BOOKED",IF(I38="Not Interested","🚫 DEAD","⏳ WORKING")))),"") | AF38: =IFERROR(IF(AE38="","",AE38-TODAY()),"") | AG38: Kristopher
A39: True HVAC LLC | B39: (801)410-6009 | C39: West Valley City | D39: Click Here | I39: Call Back | V39: =IFERROR(ROUND((IF(Q39="Severe",4,IF(Q39="Moderate",3,IF(Q39="Minor",2,0)))+IF(R39="Severe",4,IF(R39="Moderate",3,IF(R39="Minor",2,0)))+IF(S39="Severe",4,IF(S39="Moderate",3,IF(S39="Minor",2,0)))+IF(T39="Severe",4,IF(T39="Moderate",3,IF(T39="Minor",2,0))))/16*100,0),"") | AA39: =IFERROR(ROUND(IF(H39>=10,30,IF(H39>=5,20,IF(H39>=2,10,0)))+IF(K39="Yes",20,IF(K39="Unsure",10,0))+IF(W39="Yes",30,IF(W39="Later",15,0))+IFERROR(V39/100*20,0)+IF(L39="Interested",15,IF(L39="Open But Busy",10,IF(L39="Neutral",5,0))),0),"") | AB39: =IFERROR(IF(AA39>=80,"🔥 HOT",IF(AA39>=60,"✅ STRONG",IF(AA39>=40,"⚡ WARM",IF(AA39>=20,"📋 NURTURE",IF(AA39>0,"❌ COLD",""))))),"") | AC39: =IFERROR(IF(AND(AA39>=60,OR(W39="Yes",W39="Later")),"🚨 URGENT",IF(AND(AA39>=40,I39="Call Back"),"📞 CALL BACK",IF(I39="Booked Meeting","📅 BOOKED",IF(I39="Not Interested","🚫 DEAD","⏳ WORKING")))),"") | AF39: =IFERROR(IF(AE39="","",AE39-TODAY()),"") | AG39: Kristopher
A40: Superior HVAC | B40: (385)443-4813 | C40: West Valley City | D40: Click Here | V40: =IFERROR(ROUND((IF(Q40="Severe",4,IF(Q40="Moderate",3,IF(Q40="Minor",2,0)))+IF(R40="Severe",4,IF(R40="Moderate",3,IF(R40="Minor",2,0)))+IF(S40="Severe",4,IF(S40="Moderate",3,IF(S40="Minor",2,0)))+IF(T40="Severe",4,IF(T40="Moderate",3,IF(T40="Minor",2,0))))/16*100,0),"") | AA40: =IFERROR(ROUND(IF(H40>=10,30,IF(H40>=5,20,IF(H40>=2,10,0)))+IF(K40="Yes",20,IF(K40="Unsure",10,0))+IF(W40="Yes",30,IF(W40="Later",15,0))+IFERROR(V40/100*20,0)+IF(L40="Interested",15,IF(L40="Open But Busy",10,IF(L40="Neutral",5,0))),0),"") | AB40: =IFERROR(IF(AA40>=80,"🔥 HOT",IF(AA40>=60,"✅ STRONG",IF(AA40>=40,"⚡ WARM",IF(AA40>=20,"📋 NURTURE",IF(AA40>0,"❌ COLD",""))))),"") | AC40: =IFERROR(IF(AND(AA40>=60,OR(W40="Yes",W40="Later")),"🚨 URGENT",IF(AND(AA40>=40,I40="Call Back"),"📞 CALL BACK",IF(I40="Booked Meeting","📅 BOOKED",IF(I40="Not Interested","🚫 DEAD","⏳ WORKING")))),"") | AF40: =IFERROR(IF(AE40="","",AE40-TODAY()),"")
A41: Aegis Heating & Air | B41: (385)250-0687 | C41: West Valley City | D41: Click Here | V41: =IFERROR(ROUND((IF(Q41="Severe",4,IF(Q41="Moderate",3,IF(Q41="Minor",2,0)))+IF(R41="Severe",4,IF(R41="Moderate",3,IF(R41="Minor",2,0)))+IF(S41="Severe",4,IF(S41="Moderate",3,IF(S41="Minor",2,0)))+IF(T41="Severe",4,IF(T41="Moderate",3,IF(T41="Minor",2,0))))/16*100,0),"") | AA41: =IFERROR(ROUND(IF(H41>=10,30,IF(H41>=5,20,IF(H41>=2,10,0)))+IF(K41="Yes",20,IF(K41="Unsure",10,0))+IF(W41="Yes",30,IF(W41="Later",15,0))+IFERROR(V41/100*20,0)+IF(L41="Interested",15,IF(L41="Open But Busy",10,IF(L41="Neutral",5,0))),0),"") | AB41: =IFERROR(IF(AA41>=80,"🔥 HOT",IF(AA41>=60,"✅ STRONG",IF(AA41>=40,"⚡ WARM",IF(AA41>=20,"📋 NURTURE",IF(AA41>0,"❌ COLD",""))))),"") | AC41: =IFERROR(IF(AND(AA41>=60,OR(W41="Yes",W41="Later")),"🚨 URGENT",IF(AND(AA41>=40,I41="Call Back"),"📞 CALL BACK",IF(I41="Booked Meeting","📅 BOOKED",IF(I41="Not Interested","🚫 DEAD","⏳ WORKING")))),"") | AF41: =IFERROR(IF(AE41="","",AE41-TODAY()),"")
...

Sheet 🔥 HOT LEADS
A1: 🔥 HOT LEADS · FIT SCORE ≥ 60 · AUTO-PULLED FROM COMMAND TRACKER
A2: These leads are auto-ranked. Work them top-down. Update the Callback Date and they'll appear in your Follow-Up Engine.
A3: Priority | B3: Company | C3: Owner/DM | D3: Phone | E3: # Trucks | F3: Fit Score | G3: Fit Tier | H3: Pain Score | I3: Open to Meeting? | J3: Follow-Up Action | K3: Callback Date | L3: Days Until | M3: Caller
A4: =IFERROR(SORTN(FILTER({'⚡ COMMAND TRACKER'!AC5:AC204,'⚡ COMMAND TRACKER'!A5:A204,'⚡ COMMAND TRACKER'!E5:E204,'⚡ COMMAND TRACKER'!B5:B204,'⚡ COMMAND TRACKER'!H5:H204,'⚡ COMMAND TRACKER'!AA5:AA204,'⚡ COMMAND TRACKER'!AB5:AB204,'⚡ COMMAND TRACKER'!V5:V204,'⚡ COMMAND TRACKER'!W5:W204,'⚡ COMMAND TRACKER'!Z5:Z204,'⚡ COMMAND TRACKER'!AE5:AE204,'⚡ COMMAND TRACKER'!AF5:AF204,'⚡ COMMAND TRACKER'!AG5:AG204},'⚡ COMMAND TRACKER'!AA5:AA204>=60),50,0,6,FALSE),"")

Sheet 📅 FOLLOW-UP ENGINE
A1: 📅 FOLLOW-UP ENGINE · WHO TO CALL TODAY · SORTED BY URGENCY
A2: Leads with Callback Date = today or overdue. Red = overdue. Green = due today/tomorrow. Update tracker to clear.
A3: Status | B3: Company | C3: Owner/DM | D3: Phone | E3: Fit Score | F3: Fit Tier | G3: Open to Meeting? | H3: Follow-Up Action | I3: Last Call | J3: Callback Date | K3: Days Overdue
A4: =ARRAYFORMULA(IF(ISNUMBER(J4:J203),IF(INT(J4:J203)<TODAY(),"🚨 OVERDUE",IF(INT(J4:J203)<=TODAY()+1,"🔔 DUE NOW","📋 UPCOMING")),"")) | B4: =IFERROR(QUERY('⚡ COMMAND TRACKER'!:04,"select A,E,B,Y,Z,U,X,AB,AE where AE is not null order by AE asc",0),"") | K4: =IFERROR(IF(J4="","",TODAY()-INT(J4)),"")
K5: =IFERROR(IF(J5="","",TODAY()-INT(J5)),"")
K6: =IFERROR(IF(J6="","",TODAY()-INT(J6)),"")
K7: =IFERROR(IF(J7="","",TODAY()-INT(J7)),"")
K8: =IFERROR(IF(J8="","",TODAY()-INT(J8)),"")
K9: =IFERROR(IF(J9="","",TODAY()-INT(J9)),"")
K10: =IFERROR(IF(J10="","",TODAY()-INT(J10)),"")
K11: =IFERROR(IF(J11="","",TODAY()-INT(J11)),"")
K12: =IFERROR(IF(J12="","",TODAY()-INT(J12)),"")
K13: =IFERROR(IF(J13="","",TODAY()-INT(J13)),"")
K14: =IFERROR(IF(J14="","",TODAY()-INT(J14)),"")
K15: =IFERROR(IF(J15="","",TODAY()-INT(J15)),"")
K16: =IFERROR(IF(J16="","",TODAY()-INT(J16)),"")
... K203: =IFERROR(IF(J203="","",TODAY()-INT(J203)),"")

Sheet 📊 PIPELINE DASHBOARD
A1: 📊 COMMAND OS · LIVE PIPELINE DASHBOARD · AUTO-UPDATES AS YOU WORK
B3: CALL ACTIVITY | G3: PIPELINE FUNNEL
B4: TOTAL LEADS ENTERED | D4: CALLS MADE | G4: 🔥 HOT (Score ≥80) | H4: =COUNTIF('⚡ COMMAND TRACKER'!AA5:AA204,">="&80)
B5: =COUNTIF('⚡ COMMAND TRACKER'!A5:A204,"<>") | D5: =COUNTA('⚡ COMMAND TRACKER'!I5:I204) | G5: ✅ STRONG (60-79) | H5: =COUNTIFS('⚡ COMMAND TRACKER'!AA5:AA204,">="&60,'⚡ COMMAND TRACKER'!AA5:AA204,"<"&80)
G6: ⚡ WARM (40-59) | H6: =COUNTIFS('⚡ COMMAND TRACKER'!AA5:AA204,">="&40,'⚡ COMMAND TRACKER'!AA5:AA204,"<"&60)
B7: ANSWERED | D7: Emails Recived | G7: 📋 NURTURE (20-39) | H7: =COUNTIFS('⚡ COMMAND TRACKER'!AA5:AA204,">="&20,'⚡ COMMAND TRACKER'!AA5:AA204,"<"&40)
B8: =COUNTIF('⚡ COMMAND TRACKER'!I5:I204,"Answered") | D8: =COUNTIF('⚡ COMMAND TRACKER'!K5:K204,"Yes") | G8: ❌ COLD (<20) | H8: =COUNTIFS('⚡ COMMAND TRACKER'!AA5:AA204,">"&0,'⚡ COMMAND TRACKER'!AA5:AA204,"<"&20)
G9: 🚫 NOT INTERESTED | H9: =COUNTIF('⚡ COMMAND TRACKER'!I5:I204,"Not Interested")
B10: BOOKED MEETINGS | D10: OPEN CALLBACKS
B11: =COUNTIF('⚡ COMMAND TRACKER'!W5:W204,"Yes") | D11: =COUNTIF('⚡ COMMAND TRACKER'!Z5:Z204,"Call Back")
B14: CONVERSION RATES | G14: 🏆 CALLER LEADERBOARD
B15: Answer Rate | C15: =IFERROR(COUNTIF('⚡ COMMAND TRACKER'!I5:I204,"Answered")/COUNTA('⚡ COMMAND TRACKER'!I5:I204),0) | G15: 🥇 Kristopher | H15: =COUNTIF('⚡ COMMAND TRACKER'!AG5:AG204,"*Kristopher*")
B16: DM Reach Rate | C16: =IFERROR(COUNTIF('⚡ COMMAND TRACKER'!K5:K204,"Yes")/COUNTA('⚡ COMMAND TRACKER'!I5:I204),0) | G16: 🥈 Watson | H16: =COUNTIF('⚡ COMMAND TRACKER'!AG5:AG204,"*Watson*")
B17: Meeting Rate | C17: =IFERROR(COUNTIF('⚡ COMMAND TRACKER'!W5:W204,"Yes")/COUNTIF('⚡ COMMAND TRACKER'!I5:I204,"Answered"),0) | G17: 🥉 — | H17: —
B18: Hot Lead Rate | C18: =IFERROR(COUNTIF('⚡ COMMAND TRACKER'!AA5:AA204,">="&60)/COUNTIF('⚡ COMMAND TRACKER'!A5:A204,"<>"),0) | G18: 4️⃣ — | H18: —
B19: Avg Fit Score | C19: =IFERROR(AVERAGEIF('⚡ COMMAND TRACKER'!AA5:AA204,">"&0),0) | G19: 5️⃣ — | H19: —
B20: Avg Pain Score | C20: =IFERROR(AVERAGEIF('⚡ COMMAND TRACKER'!V5:V204,">"&0),0)

Sheet 📋 BOOKED MEETINGS
A1: 📋 BOOKED MEETINGS · AUTO-PULLED FROM TRACKER · SHOW TIME
A3: Company | B3: Owner/DM | C3: Phone | D3: # Trucks | E3: Meeting Type | F3: Fit Score | G3: Fit Tier | H3: Main Pain | I3: Callback Date | J3: Caller
